Workbook

Sheet RF_R10_p10
A1: FeO \ Fe | B1: 37.3072 | C1: 37.973 | D1: 38.6387 | E1: 39.3045 | F1: 39.9702 | G1: 40.636 | H1: 41.3018 | I1: 41.9675 | J1: 42.6333 | K1: 43.299 | L1: 43.9648 | M1: 44.6306 | N1: 45.2963 | O1: 45.9621 | P1: 46.6278 | Q1: 47.2936 | R1: 47.9594 | S1: 48.6251 | T1: 49.2909 | U1: 49.9566 | V1: 50.6224 | W1: 51.2882 | X1: 51.9539 | Y1: 52.6197 | Z1: 53.2854 | AA1: 53.9512 | AB1: 54.617 | AC1: 55.2827 | AD1: 55.9485 | AE1: 56.6142 | AF1: 57.28
A2: 8.93 | B2: 67.375 | C2: 67.3875 | D2: 67.3875 | E2: 67.3875 | F2: 67.411765 | G2: 67.528645 | H2: 67.583333 | I2: 67.635227 | J2: 67.646639 | K2: 67.635227 | L2: 67.694837 | M2: 68 | N2: 68.2 | O2: 68.299412 | P2: 68.318182 | Q2: 68.317133 | R2: 68.3 | S2: 68.318182 | T2: 68.331818 | U2: 68.370833 | V2: 68.2 | W2: 68.198182 | X2: 68.198182 | Y2: 68.198182 | Z2: 68.142857 | AA2: 68.165385 | AB2: 68.165385 | AC2: 68.165385 | AD2: 68.152747 | AE2: 68.152747 | AF2: 68.152747
A3: 9.4617 | B3: 67.3875 | C3: 67.416176 | D3: 67.416176 | E3: 67.416176 | F3: 67.416176 | G3: 67.438857 | H3: 67.545076 | I3: 67.6225 | J3: 67.666667 | K3: 67.665 | L3: 67.721429 | M3: 68.03913 | N3: 68.272727 | O3: 68.384615 | P3: 68.442857 | Q3: 68.427381 | R3: 68.383654 | S3: 68.427381 | T3: 68.427381 | U3: 68.384615 | V3: 68.229915 | W3: 68.209474 | X3: 68.209474 | Y3: 68.2 | Z3: 68.2 | AA3: 68.221053 | AB3: 68.268623 | AC3: 68.928022 | AD3: 69 | AE3: 69 | AF3: 69
A4: 9.9933 | B4: 67.416176 | C4: 67.459385 | D4: 67.459385 | E4: 67.438857 | F4: 67.459385 | G4: 67.459385 | H4: 67.569841 | I4: 67.571429 | J4: 67.635227 | K4: 67.666667 | L4: 67.738551 | M4: 68.086594 | N4: 68.299412 | O4: 68.415 | P4: 68.453535 | Q4: 68.413462 | R4: 68.331818 | S4: 68.413462 | T4: 68.413462 | U4: 68.413462 | V4: 68.261842 | W4: 68.229915 | X4: 68.427381 | Y4: 68.932857 | Z4: 69.099091 | AA4: 69.145 | AB4: 69.145 | AC4: 69.1 | AD4: 69.099091 | AE4: 69.099091 | AF4: 69.099091
A5: 10.525 | B5: 67.23867 | C5: 67.302484 | D5: 67.307692 | E5: 67.459385 | F5: 67.476589 | G5: 67.476589 | H5: 67.476589 | I5: 67.554545 | J5: 67.583333 | K5: 67.598824 | L5: 67.738551 | M5: 68.086594 | N5: 68.284921 | O5: 68.384615 | P5: 68.427381 | Q5: 68.413462 | R5: 68.370833 | S5: 68.427381 | T5: 68.590642 | U5: 69.352262 | V5: 69.222222 | W5: 69.17549 | X5: 69.153462 | Y5: 69.145 | Z5: 69.153462 | AA5: 69.166667 | AB5: 69.166667 | AC5: 69.165385 | AD5: 69.153462 | AE5: 69.145 | AF5: 69.145
A6: 11.0567 | B6: 67.3875 | C6: 67.315461 | D6: 67.307692 | E6: 67.145833 | F6: 67.213547 | G6: 67.312019 | H6: 67.333333 | I6: 67.3725 | J6: 67.427381 | K6: 67.497826 | L6: 67.583333 | M6: 67.949737 | N6: 68.138571 | O6: 68.293277 | P6: 68.369318 | Q6: 69.497368 | R6: 69.5 | S6: 69.665217 | T6: 69.665217 | U6: 69.587374 | V6: 69.221053 | W6: 69.181283 | X6: 69.166667 | Y6: 69.165385 | Z6: 69.165385 | AA6: 69.17549 | AB6: 69.17549 | AC6: 69.166667 | AD6: 69.165385 | AE6: 69.291071 | AF6: 69.317133
A7: 11.5883 | B7: 68.165 | C7: 67.699565 | D7: 67.64011 | E7: 67.331579 | F7: 67.331579 | G7: 67.276667 | H7: 67.116409 | I7: 67.1875 | J7: 67.307692 | K7: 67.388462 | L7: 67.598824 | M7: 68.065263 | N7: 69.139683 | O7: 69.857143 | P7: 70.051716 | Q7: 70 | R7: 69.705882 | S7: 69.888889 | T7: 69.865714 | U7: 69.798571 | V7: 69.317133 | W7: 69.24881 | X7: 69.229915 | Y7: 69.222222 | Z7: 69.222222 | AA7: 69.498 | AB7: 69.5 | AC7: 69.5 | AD7: 69.521429 | AE7: 69.585664 | AF7: 69.637662
A8: 12.12 | B8: 68.25 | C8: 68.313636 | D8: 68.313636 | E8: 68.166667 | F8: 67.747222 | G8: 67.519565 | H8: 67.411765 | I8: 67.411765 | J8: 67.331579 | K8: 67.582143 | L8: 68 | M8: 69.307358 | N8: 70.6875 | O8: 72 | P8: 72 | Q8: 70.960417 | R8: 70.24375 | S8: 70.454545 | T8: 70.412414 | U8: 70.186932 | V8: 69.798571 | W8: 69.842491 | X8: 69.915909 | Y8: 69.955667 | Z8: 70.03913 | AA8: 70.090909 | AB8: 70.11 | AC8: 70.111111 | AD8: 70.11 | AE8: 70.11 | AF8: 70.131765
A9: 12.6517 | B9: 68.313636 | C9: 68.357143 | D9: 68.357143 | E9: 68.357143 | F9: 68.357143 | G9: 68.362987 | H9: 68.221429 | I9: 68.2 | J9: 67.947076 | K9: 67.866667 | L9: 68.086594 | M9: 68.454545 | N9: 69.090909 | O9: 70.428571 | P9: 71.333333 | Q9: 71.43375 | R9: 71.147619 | S9: 71.248529 | T9: 71.181283 | U9: 70.537949 | V9: 70.1875 | W9: 70.186932 | X9: 70.186932 | Y9: 70.15749 | Z9: 70.179426 | AA9: 70.179426 | AB9: 70.248529 | AC9: 70.277273 | AD9: 70.415 | AE9: 70.4 | AF9: 70.415
A10: 13.1833 | B10: 68.25 | C10: 68.313636 | D10: 68.313636 | E10: 68.47563 | F10: 68.747222 | G10: 68.923077 | H10: 68.923077 | I10: 68.923077 | J10: 68.922769 | K10: 68.388462 | L10: 68.44375 | M10: 68.635885 | N10: 69.081667 | O10: 69.775 | P10: 69.8725 | Q10: 70.082692 | R10: 70.111111 | S10: 71.052941 | T10: 71.306923 | U10: 71.31498 | V10: 70.947076 | W10: 70.788304 | X10: 70.428571 | Y10: 70.179426 | Z10: 70.327778 | AA10: 70.333333 | AB10: 70.333333 | AC10: 70.35098 | AD10: 70.333333 | AE10: 70.333333 | AF10: 70.387468
A11: 13.715 | B11: 69.0625 | C11: 69.938235 | D11: 70.099091 | E11: 70.133838 | F11: 70.142208 | G11: 70.142208 | H11: 70.142208 | I11: 70.133838 | J11: 70.133838 | K11: 70.221429 | L11: 70.523684 | M11: 70.410588 | N11: 70.915 | O11: 71.261842 | P11: 71.435855 | Q11: 72 | R11: 71.460839 | S11: 71.398462 | T11: 71.613846 | U11: 71.635885 | V11: 71.665217 | W11: 71.874457 | X11: 71.828571 | Y11: 71.704525 | Z11: 71.634266 | AA11: 71.35098 | AB11: 71.2 | AC11: 71.2 | AD11: 71.2 | AE11: 71.2 | AF11: 71.2
A12: 14.2467 | B12: 73.328571 | C12: 73.609091 | D12: 73.715657 | E12: 73.874118 | F12: 73.874118 | G12: 74.030357 | H12: 74.030357 | I12: 73.795 | J12: 73.75 | K12: 74.030357 | L12: 76.333333 | M12: 76.849615 | N12: 77.21391 | O12: 77.5 | P12: 75.598333 | Q12: 75.265 | R12: 73.553333 | S12: 73.73134 | T12: 73.806349 | U12: 73 | V12: 72.261842 | W12: 72.333333 | X12: 72.285714 | Y12: 72.428571 | Z12: 72.534615 | AA12: 72.588961 | AB12: 72.643891 | AC12: 72.597143 | AD12: 72.33 | AE12: 72.165789 | AF12: 72.165789
A13: 14.7783 | B13: 77.413889 | C13: 77.47247 | D13: 77.497368 | E13: 77.534615 | F13: 77.534615 | G13: 77.534615 | H13: 77.560096 | I13: 77.534615 | J13: 78.699231 | K13: 78.918269 | L13: 79 | M13: 79.398889 | N13: 79.388095 | O13: 79.537247 | P13: 79.545455 | Q13: 79.388095 | R13: 76.940909 | S13: 76.35098 | T13: 76.246429 | U13: 75.265 | V13: 75 | W13: 75 | X13: 73.587745 | Y13: 73.042857 | Z13: 73.20614 | AA13: 73.226768 | AB13: 73.348333 | AC13: 73.526471 | AD13: 73.587745 | AE13: 73.61087 | AF13: 73.611111
... A32: 24.88 | B32: 86.61 | C32: 86.644853 | D32: 86.624038 | E32: 86.650962 | F32: 86.650962 | G32: 86.650962 | H32: 86.665385 | I32: 86.665385 | J32: 86.6875 | K32: 86.666667 | L32: 86.666667 | M32: 86.691827 | N32: 86.6625 | O32: 86.598333 | P32: 86.40905 | Q32: 86.5 | R32: 86.25 | S32: 86.560417 | T32: 86.582895 | U32: 86.712857 | V32: 86.763235 | W32: 86.748684 | X32: 86.777778 | Y32: 86.784921 | Z32: 86.822995 | AA32: 86.898235 | AB32: 87.212088 | AC32: 87.326667 | AD32: 87.357143 | AE32: 88 | AF32: 88.054762

Sheet RF_R10_mean
A1: FeO \ Fe | B1: 37.3072 | C1: 37.973 | D1: 38.6387 | E1: 39.3045 | F1: 39.9702 | G1: 40.636 | H1: 41.3018 | I1: 41.9675 | J1: 42.6333 | K1: 43.299 | L1: 43.9648 | M1: 44.6306 | N1: 45.2963 | O1: 45.9621 | P1: 46.6278 | Q1: 47.2936 | R1: 47.9594 | S1: 48.6251 | T1: 49.2909 | U1: 49.9566 | V1: 50.6224 | W1: 51.2882 | X1: 51.9539 | Y1: 52.6197 | Z1: 53.2854 | AA1: 53.9512 | AB1: 54.617 | AC1: 55.2827 | AD1: 55.9485 | AE1: 56.6142 | AF1: 57.28
A2: 8.93 | B2: 70.270979 | C2: 70.3 | D2: 70.3 | E2: 70.3 | F2: 70.343137 | G2: 70.5 | H2: 70.736842 | I2: 70.870833 | J2: 71 | K2: 71 | L2: 71.289916 | M2: 72.36039 | N2: 73.017241 | O2: 73.629121 | P2: 73.654762 | Q2: 73.460606 | R2: 72.780193 | S2: 73.017241 | T2: 73.112121 | U2: 73 | V2: 72.551839 | W2: 72.5 | X2: 72.4375 | Y2: 72.422619 | Z2: 72.405882 | AA2: 72.411765 | AB2: 72.414216 | AC2: 72.411765 | AD2: 72.395652 | AE2: 72.383152 | AF2: 72.405882
A3: 9.4617 | B3: 70.38796 | C3: 70.36039 | D3: 70.36039 | E3: 70.369318 | F3: 70.36039 | G3: 70.440972 | H3: 70.6 | I3: 70.848077 | J3: 71.105556 | K3: 71.189904 | L3: 71.458042 | M3: 72.464103 | N3: 73.197917 | O3: 73.75 | P3: 73.757353 | Q3: 73.550505 | R3: 72.928571 | S3: 73.217803 | T3: 73.272727 | U3: 73.145105 | V3: 72.675439 | W3: 72.644958 | X3: 72.528571 | Y3: 72.5 | Z3: 72.5 | AA3: 72.528571 | AB3: 72.923077 | AC3: 74.114379 | AD3: 74.188988 | AE3: 74.238596 | AF3: 74.286364
A4: 9.9933 | B4: 70.666667 | C4: 70.714286 | D4: 70.732143 | E4: 70.511905 | F4: 70.454545 | G4: 70.454545 | H4: 70.65 | I4: 70.725564 | J4: 70.934267 | K4: 71.341667 | L4: 71.666667 | M4: 72.705882 | N4: 73.372294 | O4: 73.972222 | P4: 73.940972 | Q4: 73.666667 | R4: 73.041051 | S4: 73.30625 | T4: 73.333333 | U4: 73.275253 | V4: 72.818015 | W4: 72.832817 | X4: 73.325758 | Y4: 74.195238 | Z4: 74.3875 | AA4: 74.416667 | AB4: 74.422619 | AC4: 74.416667 | AD4: 74.363971 | AE4: 74.363971 | AF4: 74.324561
A5: 10.525 | B5: 70.142857 | C5: 70.3 | D5: 70.352941 | E5: 70.710084 | F5: 70.766304 | G5: 70.789474 | H5: 70.525063 | I5: 70.637218 | J5: 70.813853 | K5: 70.94281 | L5: 71.666667 | M5: 72.954453 | N5: 73.36039 | O5: 73.935417 | P5: 73.933333 | Q5: 73.629121 | R5: 73.017241 | S5: 73.353571 | T5: 73.881176 | U5: 74.768889 | V5: 74.526611 | W5: 74.5 | X5: 74.416667 | Y5: 74.408333 | Z5: 74.416667 | AA5: 74.416667 | AB5: 74.422619 | AC5: 74.333333 | AD5: 74.286364 | AE5: 74.238596 | AF5: 74.125
A6: 11.0567 | B6: 70.939338 | C6: 70.780193 | D6: 70.488095 | E6: 70.083333 | F6: 70.214286 | G6: 70.456439 | H6: 70.6 | I6: 70.613248 | J6: 70.833333 | K6: 70.766304 | L6: 71 | M6: 72.803846 | N6: 73.470175 | O6: 74 | P6: 74.091667 | Q6: 75.417423 | R6: 74.755 | S6: 75.0625 | T6: 75.095455 | U6: 75 | V6: 74.585784 | W6: 74.541958 | X6: 74.488095 | Y6: 74.351471 | Z6: 74.324561 | AA6: 74.341667 | AB6: 74.269697 | AC6: 74.139423 | AD6: 74.111111 | AE6: 74.472136 | AF6: 74.466063
A7: 11.5883 | B7: 78.55614 | C7: 72.603147 | D7: 72.215278 | E7: 70.857143 | F7: 70.75 | G7: 70.352941 | H7: 70.083333 | I7: 70.205263 | J7: 70.5 | K7: 70.912879 | L7: 71.6 | M7: 73.675439 | N7: 75.404545 | O7: 75.882353 | P7: 75.743421 | Q7: 75.550505 | R7: 74.857143 | S7: 75.0625 | T7: 75.059028 | U7: 74.892308 | V7: 74.541958 | W7: 74.5 | X7: 74.333333 | Y7: 74.238636 | Z7: 74.213636 | AA7: 74.531373 | AB7: 74.529412 | AC7: 74.563859 | AD7: 74.607692 | AE7: 74.820513 | AF7: 74.839744
A8: 12.12 | B8: 78.801948 | C8: 78.830144 | D8: 78.830144 | E8: 76.894444 | F8: 73.046653 | G8: 71.563492 | H8: 71.25 | I8: 71.15587 | J8: 70.629085 | K8: 71.6875 | L8: 72.916667 | M8: 74.095455 | N8: 75.108187 | O8: 76 | P8: 76.262014 | Q8: 75.755952 | R8: 74.937739 | S8: 75.0625 | T8: 75.085145 | U8: 74.912879 | V8: 74.565217 | W8: 74.588235 | X8: 74.707108 | Y8: 74.68375 | Z8: 74.788889 | AA8: 75.059028 | AB8: 75.085145 | AC8: 75.111111 | AD8: 75.111111 | AE8: 75.131429 | AF8: 75.295833
A9: 12.6517 | B9: 78.9375 | C9: 79 | D9: 78.854386 | E9: 78.870833 | F9: 78.870833 | G9: 78.696154 | H9: 74.794737 | I9: 74.263768 | J9: 73.060662 | K9: 72.925824 | L9: 73.233032 | M9: 73.278889 | N9: 73.794737 | O9: 74.724747 | P9: 75 | Q9: 74.95119 | R9: 74.724747 | S9: 74.95119 | T9: 75.037857 | U9: 74.633971 | V9: 74.473684 | W9: 74.5 | X9: 74.588235 | Y9: 74.594118 | Z9: 74.673333 | AA9: 74.699095 | AB9: 74.781746 | AC9: 74.848077 | AD9: 75.157895 | AE9: 75.158947 | AF9: 75.157895
A10: 13.1833 | B10: 79.08194 | C10: 79.08194 | D10: 79.08194 | E10: 79.38796 | F10: 79.575188 | G10: 79.658333 | H10: 79.575188 | I10: 79.555336 | J10: 79.379808 | K10: 74.529412 | L10: 74.333333 | M10: 73.6 | N10: 73.940972 | O10: 74.231283 | P10: 74.235294 | Q10: 74.222222 | R10: 73.85641 | S10: 74.384615 | T10: 74.724747 | U10: 75 | V10: 75 | W10: 75 | X10: 74.692308 | Y10: 74.673333 | Z10: 74.925824 | AA10: 75.02 | AB10: 75.041739 | AC10: 75.083333 | AD10: 75.083333 | AE10: 75.085145 | AF10: 75.111111
A11: 13.715 | B11: 81.872283 | C11: 82.021739 | D11: 82.071795 | E11: 82.066667 | F11: 82.021739 | G11: 82.021739 | H11: 82 | I11: 81.933333 | J11: 81.922619 | K11: 81.912879 | L11: 81.885621 | M11: 78.809091 | N11: 78.292857 | O11: 77.366029 | P11: 77.083333 | Q11: 77.121324 | R11: 76.356471 | S11: 76 | T11: 76.233032 | U11: 76.310096 | V11: 76.369318 | W11: 76.761364 | X11: 76.904762 | Y11: 77.080128 | Z11: 77.171569 | AA11: 77.122222 | AB11: 77.076923 | AC11: 77.089286 | AD11: 77.14359 | AE11: 77.153846 | AF11: 77.156923
A12: 14.2467 | B12: 85.9375 | C12: 86 | D12: 86.076923 | E12: 86.076923 | F12: 86.076923 | G12: 86 | H12: 85.8 | I12: 85.594118 | J12: 85.5 | K12: 85.091667 | L12: 85.333333 | M12: 85.5 | N12: 85.563937 | O12: 85.511905 | P12: 80.833333 | Q12: 80.52381 | R12: 79.416667 | S12: 79.563859 | T12: 80.420168 | U12: 80.477273 | V12: 80.208696 | W12: 80.384615 | X12: 80.333333 | Y12: 80.374126 | Z12: 80.477273 | AA12: 80.769231 | AB12: 80.795139 | AC12: 80.895238 | AD12: 80.933333 | AE12: 80.938889 | AF12: 80.978261
A13: 14.7783 | B13: 88.647059 | C13: 88.649616 | D13: 88.541958 | E13: 88.69398 | F13: 88.904762 | G13: 89.083333 | H13: 89.125 | I13: 89 | J13: 88.639319 | K13: 87.8 | L13: 87.594118 | M13: 87.761663 | N13: 87.674242 | O13: 88 | P13: 88.21131 | Q13: 87.8 | R13: 84.449495 | S13: 83.8125 | T13: 84 | U13: 84.138095 | V13: 85.158333 | W13: 85.473684 | X13: 85.415072 | Y13: 85.104356 | Z13: 85.101724 | AA13: 85.320513 | AB13: 85.446558 | AC13: 85.486842 | AD13: 85.514706 | AE13: 85.541958 | AF13: 85.553977
... A32: 24.88 | B32: 91.461538 | C32: 91.424812 | D32: 91.4 | E32: 91.30602 | F32: 91.302174 | G32: 91.302174 | H32: 91.302174 | I32: 91.3 | J32: 91.310096 | K32: 91.307692 | L32: 91.292892 | M32: 91.307692 | N32: 91.255435 | O32: 91.190909 | P32: 90.930952 | Q32: 90.923077 | R32: 90.861905 | S32: 91.275253 | T32: 91.26087 | U32: 91.452273 | V32: 91.647516 | W32: 91.743421 | X32: 91.870833 | Y32: 91.919872 | Z32: 92.026316 | AA32: 93.464103 | AB32: 94.266798 | AC32: 94.494681 | AD32: 95.167832 | AE32: 103.59943 | AF32: 103.92582

Sheet RF_R10_p90
A1: FeO \ Fe | B1: 37.3072 | C1: 37.973 | D1: 38.6387 | E1: 39.3045 | F1: 39.9702 | G1: 40.636 | H1: 41.3018 | I1: 41.9675 | J1: 42.6333 | K1: 43.299 | L1: 43.9648 | M1: 44.6306 | N1: 45.2963 | O1: 45.9621 | P1: 46.6278 | Q1: 47.2936 | R1: 47.9594 | S1: 48.6251 | T1: 49.2909 | U1: 49.9566 | V1: 50.6224 | W1: 51.2882 | X1: 51.9539 | Y1: 52.6197 | Z1: 53.2854 | AA1: 53.9512 | AB1: 54.617 | AC1: 55.2827 | AD1: 55.9485 | AE1: 56.6142 | AF1: 57.28
A2: 8.93 | B2: 76.143386 | C2: 76.357143 | D2: 76.375595 | E2: 76.429714 | F2: 76.429714 | G2: 76.644156 | H2: 76.934118 | I2: 77.095238 | J2: 77.601111 | K2: 77.639394 | L2: 77.705 | M2: 77.958333 | N2: 78.083333 | O2: 78.335 | P2: 78.45615 | Q2: 78.401176 | R2: 78.22381 | S2: 78.263509 | T2: 78.473529 | U2: 78.643277 | V2: 78.834615 | W2: 78.847253 | X2: 78.818717 | Y2: 78.818717 | Z2: 78.818717 | AA2: 78.847253 | AB2: 78.847253 | AC2: 78.847253 | AD2: 78.858095 | AE2: 78.858095 | AF2: 78.866667
A3: 9.4617 | B3: 76.5 | C3: 76.504545 | D3: 76.557895 | E3: 76.637013 | F3: 76.60087 | G3: 76.768235 | H3: 76.883007 | I3: 77 | J3: 77.45671 | K3: 77.700588 | L3: 77.857143 | M3: 78 | N3: 78.143956 | O3: 78.4 | P3: 78.5 | Q3: 78.454545 | R3: 78.28 | S3: 78.308173 | T3: 78.539161 | U3: 78.682057 | V3: 78.858095 | W3: 78.866667 | X3: 78.834615 | Y3: 78.834615 | Z3: 78.834615 | AA3: 78.866667 | AB3: 78.917308 | AC3: 79.101111 | AD3: 79.183636 | AE3: 79.183636 | AF3: 79.2
A4: 9.9933 | B4: 76.375595 | C4: 76.859664 | D4: 77.153846 | E4: 77.046823 | F4: 76.884118 | G4: 76.84251 | H4: 77 | I4: 77 | J4: 77.004348 | K4: 77.6 | L4: 77.8675 | M4: 78.006667 | N4: 78.168182 | O4: 78.429464 | P4: 78.548052 | Q4: 78.473529 | R4: 78.308173 | S4: 78.333333 | T4: 78.548052 | U4: 78.687981 | V4: 78.866667 | W4: 78.866667 | X4: 78.924103 | Y4: 79.083333 | Z4: 79.101111 | AA4: 79.201429 | AB4: 79.201429 | AC4: 79.2 | AD4: 79.2 | AE4: 79.2 | AF4: 79.2
A5: 10.525 | B5: 75.632057 | C5: 76.172222 | D5: 76.145238 | E5: 76.64902 | F5: 77 | G5: 77.275455 | H5: 77.095714 | I5: 77 | J5: 77 | K5: 77.150789 | L5: 77.875735 | M5: 78.168182 | N5: 78.2 | O5: 78.445 | P5: 78.571429 | Q5: 78.5 | R5: 78.333333 | S5: 78.350714 | T5: 78.64902 | U5: 78.900476 | V5: 79.118182 | W5: 79.2 | X5: 79.118182 | Y5: 79.118182 | Z5: 79.118182 | AA5: 79.201429 | AB5: 79.215934 | AC5: 79.2 | AD5: 79.2 | AE5: 79.2 | AF5: 79.2
A6: 11.0567 | B6: 79.375 | C6: 78.503333 | D6: 77.790526 | E6: 75.905195 | F6: 76.30042 | G6: 76.546465 | H6: 76.735 | I6: 76.946667 | J6: 77.214596 | K6: 77.319697 | L6: 77.459091 | M6: 78.2 | N6: 78.3 | O6: 78.45615 | P6: 78.601111 | Q6: 78.75 | R6: 78.6 | S6: 78.611111 | T6: 78.818717 | U6: 78.933333 | V6: 79.210902 | W6: 79.215934 | X6: 79.210902 | Y6: 79.201053 | Z6: 79.201053 | AA6: 79.231222 | AB6: 79.231222 | AC6: 79.201053 | AD6: 79.201053 | AE6: 79.400909 | AF6: 79.400909
A7: 11.5883 | B7: 93.215079 | C7: 84.719328 | D7: 83.818182 | E7: 78.762637 | F7: 78.412255 | G7: 76.813187 | H7: 75.883007 | I7: 76.125543 | J7: 76.223077 | K7: 76.75 | L7: 77.382857 | M7: 78 | N7: 78.557143 | O7: 78.727879 | P7: 78.75 | Q7: 78.702727 | R7: 78.548052 | S7: 78.57218 | T7: 78.770085 | U7: 78.905195 | V7: 79.101111 | W7: 79.118182 | X7: 79.085 | Y7: 79.083333 | Z7: 79.083333 | AA7: 79.367273 | AB7: 79.367273 | AC7: 79.476316 | AD7: 79.579386 | AE7: 80.129167 | AF7: 80.502632
A8: 12.12 | B8: 93.1875 | C8: 93.302198 | D8: 93.275613 | E8: 92.167021 | F8: 84.30125 | G8: 80.067788 | H8: 78.702727 | I8: 78.314583 | J8: 76.687218 | K8: 76.942513 | L8: 77.201429 | M8: 77.571429 | N8: 77.929464 | O8: 78.546465 | P8: 78.78 | Q8: 78.617004 | R8: 78.401667 | S8: 78.417105 | T8: 78.637013 | U8: 78.818717 | V8: 78.95 | W8: 79.083333 | X8: 79.294706 | Y8: 79.336364 | Z8: 79.5 | AA8: 80.17 | AB8: 80.431868 | AC8: 80.924103 | AD8: 81.381818 | AE8: 81.835145 | AF8: 83.663603
A9: 12.6517 | B9: 93.3375 | C9: 93.23808 | D9: 93.215079 | E9: 93.23808 | F9: 93.182386 | G9: 92.951429 | H9: 85.335 | I9: 83.858095 | J9: 79.692308 | K9: 79.212551 | L9: 78.91875 | M9: 77.158772 | N9: 77.158772 | O9: 77.666667 | P9: 78.059608 | Q9: 78 | R9: 78 | S9: 78.2 | T9: 78.611538 | U9: 78.703333 | V9: 79.231222 | W9: 79.400909 | X9: 80.081091 | Y9: 80.389011 | Z9: 81.214286 | AA9: 81.303333 | AB9: 83.201429 | AC9: 83.817917 | AD9: 87.586538 | AE9: 87.669231 | AF9: 87.702
A10: 13.1833 | B10: 94 | C10: 93.6 | D10: 93.3375 | E10: 93.417857 | F10: 93.264115 | G10: 93.058333 | H10: 92.951429 | I10: 92.601905 | J10: 92.154251 | K10: 84.3125 | L10: 83.8125 | M10: 79.565839 | N10: 79.39 | O10: 78.6025 | P10: 77.944737 | Q10: 78 | R10: 77.546465 | S10: 77.90559 | T10: 78.4 | U10: 79.5 | V10: 80.385043 | W10: 81.216387 | X10: 81.241765 | Y10: 83.365667 | Z10: 87.007143 | AA10: 87.620513 | AB10: 87.620513 | AC10: 88.598684 | AD10: 88.753947 | AE10: 88.790526 | AF10: 88.945263
A11: 13.715 | B11: 94.137621 | C11: 94.126136 | D11: 94.083333 | E11: 93.666667 | F11: 93.481316 | G11: 93.417857 | H11: 93.215079 | I11: 92.841667 | J11: 92.462051 | K11: 91.803051 | L11: 91.411039 | M11: 86.0625 | N11: 84.645238 | O11: 82.470898 | P11: 81.95 | Q11: 81.79375 | R11: 81.236765 | S11: 80.91049 | T11: 82.349407 | U11: 82.800952 | V11: 85.620513 | W11: 87.738909 | X11: 88.208571 | Y11: 88.291758 | Z11: 88.962406 | AA11: 89.3525 | AB11: 89.452059 | AC11: 89.78 | AD11: 89.945238 | AE11: 89.953143 | AF11: 90
A12: 14.2467 | B12: 95.093357 | C12: 95.232692 | D12: 95.526429 | E12: 95.412255 | F12: 95.5 | G12: 95.312829 | H12: 94.502632 | I12: 94.282418 | J12: 94.083333 | K12: 93.250899 | L12: 93 | M12: 93.401667 | N12: 93.417857 | O12: 93.721333 | P12: 88.800952 | Q12: 88.169048 | R12: 87.01 | S12: 87.251316 | T12: 88.37663 | U12: 90 | V12: 92 | W12: 92.693665 | X12: 93.005556 | Y12: 93.005556 | Z12: 93.4 | AA12: 93.833333 | AB12: 93.847253 | AC12: 93.833333 | AD12: 93.863736 | AE12: 94 | AF12: 94.205
A13: 14.7783 | B13: 95.945455 | C13: 96.067692 | D13: 95.954924 | E13: 96.067692 | F13: 96.232692 | G13: 96.429464 | H13: 96.469231 | I13: 96.252273 | J13: 95.714286 | K13: 94.959091 | L13: 94.666667 | M13: 95.134286 | N13: 94.700588 | O13: 95.232692 | P13: 96.055556 | Q13: 96.415033 | R13: 93.720727 | S13: 93.223077 | T13: 92.729545 | U13: 91.9 | V13: 94.470588 | W13: 94.729545 | X13: 95 | Y13: 95 | Z13: 95.005 | AA13: 95.565362 | AB13: 95.632421 | AC13: 95.66875 | AD13: 95.732323 | AE13: 95.790526 | AF13: 95.8
... A32: 24.88 | B32: 98.232692 | C32: 98.047188 | D32: 98 | E32: 97.883591 | F32: 97.883591 | G32: 97.882353 | H32: 97.835 | I32: 97.835 | J32: 97.835 | K32: 97.833333 | L32: 97.833333 | M32: 97.882353 | N32: 97.689338 | O32: 97.638112 | P32: 97.005556 | Q32: 96.778261 | R32: 96.65045 | S32: 97.67619 | T32: 97.239773 | U32: 98.835 | V32: 99.5 | W32: 99.842857 | X32: 100.51524 | Y32: 101.36573 | Z32: 102.34167 | AA32: 107.33333 | AB32: 107.37596 | AC32: 107.66842 | AD32: 107.77857 | AE32: 108.14357 | AF32: 108.23676

Sheet RF_R50_p10
A1: FeO \ Fe | B1: 37.3072 | C1: 37.973 | D1: 38.6387 | E1: 39.3045 | F1: 39.9702 | G1: 40.636 | H1: 41.3018 | I1: 41.9675 | J1: 42.6333 | K1: 43.299 | L1: 43.9648 | M1: 44.6306 | N1: 45.2963 | O1: 45.9621 | P1: 46.6278 | Q1: 47.2936 | R1: 47.9594 | S1: 48.6251 | T1: 49.2909 | U1: 49.9566 | V1: 50.6224 | W1: 51.2882 | X1: 51.9539 | Y1: 52.6197 | Z1: 53.2854 | AA1: 53.9512 | AB1: 54.617 | AC1: 55.2827 | AD1: 55.9485 | AE1: 56.6142 | AF1: 57.28
A2: 8.93 | B2: 67.298571 | C2: 67.298571 | D2: 67.298571 | E2: 67.298571 | F2: 67.303913 | G2: 67.375 | H2: 67.410588 | I2: 67.398889 | J2: 67.411765 | K2: 67.411765 | L2: 67.497826 | M2: 67.666667 | N2: 67.732222 | O2: 67.8 | P2: 67.833333 | Q2: 67.833333 | R2: 67.882353 | S2: 67.935417 | T2: 67.996429 | U2: 68 | V2: 68 | W2: 68.03913 | X2: 68.03913 | Y2: 68.03913 | Z2: 68 | AA2: 68 | AB2: 68 | AC2: 68 | AD2: 68 | AE2: 68 | AF2: 68
A3: 9.4617 | B3: 67.284921 | C3: 67.298571 | D3: 67.298571 | E3: 67.298571 | F3: 67.298571 | G3: 67.298571 | H3: 67.307358 | I3: 67.383654 | J3: 67.410588 | K3: 67.411765 | L3: 67.497826 | M3: 67.666667 | N3: 67.732222 | O3: 67.798571 | P3: 67.83125 | Q3: 67.83125 | R3: 67.882118 | S3: 67.916304 | T3: 67.949444 | U3: 67.962857 | V3: 68 | W3: 68 | X3: 68 | Y3: 67.996429 | Z3: 67.996429 | AA3: 67.996429 | AB3: 68 | AC3: 68.544755 | AD3: 68.6 | AE3: 68.615385 | AF3: 68.615385
A4: 9.9933 | B4: 67.285714 | C4: 67.285714 | D4: 67.285714 | E4: 67.285714 | F4: 67.298571 | G4: 67.285714 | H4: 67.307358 | I4: 67.285714 | J4: 67.375 | K4: 67.411765 | L4: 67.497826 | M4: 67.666667 | N4: 67.722222 | O4: 67.785714 | P4: 67.81125 | Q4: 67.798571 | R4: 67.854762 | S4: 67.908658 | T4: 67.916667 | U4: 67.935417 | V4: 67.962857 | W4: 67.996429 | X4: 68.152747 | Y4: 68.544755 | Z4: 68.615385 | AA4: 68.615385 | AB4: 68.615385 | AC4: 68.615385 | AD4: 68.615385 | AE4: 68.615385 | AF4: 68.615385
A5: 10.525 | B5: 67.124265 | C5: 67.1875 | D5: 67.19875 | E5: 67.285714 | F5: 67.285714 | G5: 67.285714 | H5: 67.25 | I5: 67.266087 | J5: 67.307692 | K5: 67.370833 | L5: 67.497826 | M5: 67.666667 | N5: 67.694837 | O5: 67.722222 | P5: 67.782143 | Q5: 67.748684 | R5: 67.83125 | S5: 67.888235 | T5: 68.06625 | U5: 68.444444 | V5: 68.598824 | W5: 68.6 | X5: 68.6 | Y5: 68.6 | Z5: 68.6 | AA5: 68.6 | AB5: 68.6 | AC5: 68.6 | AD5: 68.6 | AE5: 68.6 | AF5: 68.6
A6: 11.0567 | B6: 67.266667 | C6: 67.213547 | D6: 67.1875 | E6: 67.06625 | F6: 67.082692 | G6: 67.1875 | H6: 67.116993 | I6: 67.110526 | J6: 67.166667 | K6: 67.1875 | L6: 67.276667 | M6: 67.5625 | N6: 67.6 | O6: 67.666667 | P6: 67.666667 | Q6: 68.17549 | R6: 68.333333 | S6: 68.427381 | T6: 68.496154 | U6: 68.5 | V6: 68.529412 | W6: 68.537557 | X6: 68.537557 | Y6: 68.537557 | Z6: 68.537557 | AA6: 68.537557 | AB6: 68.537557 | AC6: 68.537557 | AD6: 68.537557 | AE6: 68.704525 | AF6: 68.817614
A7: 11.5883 | B7: 67.995 | C7: 67.541346 | D7: 67.497826 | E7: 67.1875 | F7: 67.1875 | G7: 67.082692 | H7: 66.95462 | I7: 67 | J7: 67.06625 | K7: 67.110526 | L7: 67.259783 | M7: 67.541346 | N7: 68.061513 | O7: 68.198182 | P7: 68.25 | Q7: 68.263158 | R7: 68.349783 | S7: 68.444444 | T7: 68.5 | U7: 68.529412 | V7: 68.554545 | W7: 68.564251 | X7: 68.564251 | Y7: 68.564251 | Z7: 68.564251 | AA7: 68.8125 | AB7: 68.844872 | AC7: 68.846154 | AD7: 68.873214 | AE7: 68.923077 | AF7: 68.923077
A8: 12.12 | B8: 68.103828 | C8: 68.103828 | D8: 68.103828 | E8: 68 | F8: 67.598824 | G8: 67.331579 | H8: 67.240318 | I8: 67.19875 | J8: 67.086594 | K8: 67.25 | L8: 67.472982 | M8: 68.131111 | N8: 68.349783 | O8: 68.5 | P8: 68.615385 | Q8: 68.5 | R8: 68.5 | S8: 68.571429 | T8: 68.598824 | U8: 68.61 | V8: 68.641729 | W8: 68.720588 | X8: 68.922436 | Y8: 68.947076 | Z8: 69 | AA8: 69.099091 | AB8: 69.123026 | AC8: 69.165385 | AD8: 69.165385 | AE8: 69.166667 | AF8: 69.221429
A9: 12.6517 | B9: 68.428571 | C9: 68.428571 | D9: 68.428571 | E9: 68.428571 | F9: 68.386842 | G9: 68.428571 | H9: 68.165385 | I9: 68.06625 | J9: 67.699231 | K9: 67.64011 | L9: 67.881618 | M9: 67.940909 | N9: 68.198182 | O9: 68.459829 | P9: 68.776471 | Q9: 68.856044 | R9: 68.923077 | S9: 69.099091 | T9: 69.333333 | U9: 69.123026 | V9: 69.229915 | W9: 69.24881 | X9: 69.424845 | Y9: 69.437228 | Z9: 69.453535 | AA9: 69.453535 | AB9: 69.479368 | AC9: 69.5 | AD9: 69.631818 | AE9: 69.631818 | AF9: 69.631818
A10: 13.1833 | B10: 68.5 | C10: 68.5 | D10: 68.5 | E10: 68.624405 | F10: 68.833333 | G10: 68.919667 | H10: 68.841228 | I10: 68.770455 | J10: 68.722222 | K10: 68.25 | L10: 68.346377 | M10: 68.346377 | N10: 68.453535 | O10: 68.6875 | P10: 68.5 | Q10: 68.832353 | R10: 68.955314 | S10: 69.649286 | T10: 69.798261 | U10: 69.932857 | V10: 70 | W10: 69.928571 | X10: 69.727273 | Y10: 69.642857 | Z10: 69.759048 | AA10: 69.759048 | AB10: 69.764426 | AC10: 69.798261 | AD10: 69.798261 | AE10: 69.798261 | AF10: 69.8
A11: 13.715 | B11: 69.5 | C11: 70.903896 | D11: 71.197647 | E11: 71.22 | F11: 71.279365 | G11: 71.22 | H11: 70.996296 | I11: 70.843357 | J11: 70.788787 | K11: 70.856044 | L11: 71.328571 | M11: 70.720588 | N11: 70.822995 | O11: 71.21391 | P11: 71.248077 | Q11: 71.460839 | R11: 71.330769 | S11: 71.307692 | T11: 71.591228 | U11: 71.64011 | V11: 71.8975 | W11: 71.996154 | X11: 71.961037 | Y11: 71.949118 | Z11: 71.949118 | AA11: 71.5 | AB11: 71.304701 | AC11: 71.304701 | AD11: 71.304701 | AE11: 71.304701 | AF11: 71.304701
A12: 14.2467 | B12: 79.315775 | C12: 79.383992 | D12: 79.454515 | E12: 79.496154 | F12: 79.496154 | G12: 79.519565 | H12: 79.48913 | I12: 79.315775 | J12: 79.281373 | K12: 79.369318 | L12: 81.590476 | M12: 81.8725 | N12: 82.176136 | O12: 81.712088 | P12: 77.460385 | Q12: 77.272727 | R12: 75.521429 | S12: 75.932308 | T12: 77.042857 | U12: 76.124265 | V12: 73.94375 | W12: 74.59625 | X12: 74.553618 | Y12: 74.744231 | Z12: 74.886957 | AA12: 74.886957 | AB12: 74.944444 | AC12: 74.89222 | AD12: 74.313333 | AE12: 73.94375 | AF12: 73.94375
A13: 14.7783 | B13: 83.367943 | C13: 83.375 | D13: 83.461538 | E13: 83.641729 | F13: 83.646639 | G13: 83.646639 | H13: 83.7 | I13: 83.713445 | J13: 84.370833 | K13: 84.085953 | L13: 84 | M13: 84.165385 | N13: 84.272121 | O13: 84.272121 | P13: 83.960623 | Q13: 83.798261 | R13: 81.545 | S13: 81.093071 | T13: 81.460839 | U13: 81.299412 | V13: 82.131765 | W13: 82.231765 | X13: 81.123026 | Y13: 79.53 | Z13: 79.537949 | AA13: 79.53 | AB13: 79.544755 | AC13: 79.544755 | AD13: 79.658333 | AE13: 79.758974 | AF13: 79.758974
... A32: 24.88 | B32: 88.299412 | C32: 88.383654 | D32: 88.5 | E32: 88.5 | F32: 88.5 | G32: 88.5 | H32: 88.55 | I32: 88.55 | J32: 88.635227 | K32: 88.676286 | L32: 88.642208 | M32: 88.68675 | N32: 88.726768 | O32: 88.727273 | P32: 88.624038 | Q32: 88.614957 | R32: 88.614957 | S32: 89.117421 | T32: 89.180303 | U32: 89.411497 | V32: 89.544755 | W32: 89.8 | X32: 90.436607 | Y32: 90.5 | Z32: 90.533333 | AA32: 92.666667 | AB32: 93.271542 | AC32: 93.450758 | AD32: 94.090152 | AE32: 101.92662 | AF32: 102.31088

Sheet RF_R50_mean
A1: FeO \ Fe | B1: 37.3072 | C1: 37.973 | D1: 38.6387 | E1: 39.3045 | F1: 39.9702 | G1: 40.636 | H1: 41.3018 | I1: 41.9675 | J1: 42.6333 | K1: 43.299 | L1: 43.9648 | M1: 44.6306 | N1: 45.2963 | O1: 45.9621 | P1: 46.6278 | Q1: 47.2936 | R1: 47.9594 | S1: 48.6251 | T1: 49.2909 | U1: 49.9566 | V1: 50.6224 | W1: 51.2882 | X1: 51.9539 | Y1: 52.6197 | Z1: 53.2854 | AA1: 53.9512 | AB1: 54.617 | AC1: 55.2827 | AD1: 55.9485 | AE1: 56.6142 | AF1: 57.28
A2: 8.93 | B2: 70.02 | C2: 70.02 | D2: 70 | E2: 70 | F2: 70 | G2: 70.090909 | H2: 70.146429 | I2: 70.13961 | J2: 70.186147 | K2: 70.205263 | L2: 70.333333 | M2: 70.780193 | N2: 71 | O2: 71.281746 | P2: 71.333333 | Q2: 71.322917 | R2: 71.292857 | S2: 71.5 | T2: 71.585784 | U2: 71.666667 | V2: 71.853571 | W2: 71.857143 | X2: 71.857143 | Y2: 71.861905 | Z2: 71.839744 | AA2: 71.848077 | AB2: 71.853571 | AC2: 71.861905 | AD2: 71.853571 | AE2: 71.853571 | AF2: 71.853571
A3: 9.4617 | B3: 70.077381 | C3: 70.02 | D3: 70 | E3: 70 | F3: 70 | G3: 70 | H3: 70.02 | I3: 70.074176 | J3: 70.17029 | K3: 70.231283 | L3: 70.333333 | M3: 70.775253 | N3: 71 | O3: 71.275253 | P3: 71.333333 | Q3: 71.30625 | R3: 71.285714 | S3: 71.5 | T3: 71.58114 | U3: 71.644958 | V3: 71.792857 | W3: 71.8 | X3: 71.839744 | Y3: 71.816667 | Z3: 71.816667 | AA3: 71.839744 | AB3: 71.933333 | AC3: 72.93797 | AD3: 73.046537 | AE3: 73.053221 | AF3: 73.066964
A4: 9.9933 | B4: 70.25 | C4: 70.235294 | D4: 70.205263 | E4: 70.052632 | F4: 70 | G4: 70 | H4: 70 | I4: 70 | J4: 70.041739 | K4: 70.220779 | L4: 70.333333 | M4: 70.766364 | N4: 71 | O4: 71.272727 | P4: 71.322917 | Q4: 71.281746 | R4: 71.267943 | S4: 71.466667 | T4: 71.570724 | U4: 71.63961 | V4: 71.792857 | W4: 71.8 | X4: 72.087121 | Y4: 72.888545 | Z4: 73.036472 | AA4: 73.044466 | AB4: 73.053221 | AC4: 73.053221 | AD4: 73.060662 | AE4: 73.066964 | AF4: 73.044466
A5: 10.525 | B5: 69.828431 | C5: 69.935417 | D5: 69.935417 | E5: 70.153846 | F5: 70.15 | G5: 70.095455 | H5: 69.933333 | I5: 69.861905 | J5: 69.933333 | K5: 70 | L5: 70.272727 | M5: 70.705882 | N5: 70.851648 | O5: 71.076923 | P5: 71.160256 | Q5: 71.142857 | R5: 71.180195 | S5: 71.386752 | T5: 71.712941 | U5: 72.5 | V5: 72.781746 | W5: 72.794737 | X5: 72.787594 | Y5: 72.794737 | Z5: 72.837719 | AA5: 72.846053 | AB5: 72.878676 | AC5: 72.888545 | AD5: 72.888545 | AE5: 72.866071 | AF5: 72.781746
A6: 11.0567 | B6: 70.292857 | C6: 70.108187 | D6: 69.979167 | E6: 69.575188 | F6: 69.651087 | G6: 69.833333 | H6: 69.842105 | I6: 69.75 | J6: 69.823529 | K6: 69.811012 | L6: 69.885621 | M6: 70.5 | N6: 70.65 | O6: 70.866667 | P6: 70.955166 | Q6: 71.8875 | R6: 72 | S6: 72.236695 | T6: 72.348077 | U6: 72.455769 | V6: 72.633971 | W6: 72.633971 | X6: 72.623482 | Y6: 72.63961 | Z6: 72.63961 | AA6: 72.644958 | AB6: 72.583591 | AC6: 72.539706 | AD6: 72.526611 | AE6: 73 | AF6: 73.044466
A7: 11.5883 | B7: 79.099034 | C7: 71.641876 | D7: 71.333333 | E7: 70.1 | F7: 70 | G7: 69.69398 | H7: 69.456439 | I7: 69.466667 | J7: 69.636364 | K7: 69.833333 | L7: 70.087121 | M7: 70.75 | N7: 71.745968 | O7: 72.055556 | P7: 72.083916 | Q7: 72.083916 | R7: 72.071429 | S7: 72.316986 | T7: 72.424812 | U7: 72.539706 | V7: 72.735088 | W7: 72.727273 | X7: 72.63961 | Y7: 72.61204 | Z7: 72.61204 | AA7: 73.051587 | AB7: 73.081667 | AC7: 73.184659 | AD7: 73.261364 | AE7: 73.422619 | AF7: 73.5
A8: 12.12 | B8: 79.897619 | C8: 79.964286 | D8: 80.060662 | E8: 76.925824 | F8: 72 | G8: 70.526316 | H8: 70.15 | I8: 70 | J8: 69.69398 | K8: 70.311741 | L8: 70.861905 | M8: 71.848571 | N8: 72.5 | O8: 73 | P8: 73 | Q8: 72.36039 | R8: 72.13961 | S8: 72.428571 | T8: 72.623482 | U8: 72.689904 | V8: 72.759615 | W8: 72.866071 | X8: 73.090909 | Y8: 73.188988 | Z8: 73.292857 | AA8: 73.5 | AB8: 73.617216 | AC8: 73.680909 | AD8: 73.766968 | AE8: 73.782609 | AF8: 73.922619
A9: 12.6517 | B9: 81.46875 | C9: 81.5 | D9: 81.5 | E9: 81.45 | F9: 81.45 | G9: 81.083333 | H9: 74 | I9: 73.428571 | J9: 71.919872 | K9: 71.636364 | L9: 72 | M9: 71.666667 | N9: 72 | O9: 72.642857 | P9: 72.875 | Q9: 72.875 | R9: 72.786041 | S9: 73.078462 | T9: 73.333333 | U9: 73.15587 | V9: 73.363636 | W9: 73.458333 | X9: 73.686154 | Y9: 73.766968 | Z9: 73.885621 | AA9: 73.891813 | AB9: 74 | AC9: 74.095455 | AD9: 74.6 | AE9: 74.6 | AF9: 74.6
A10: 13.1833 | B10: 82.684848 | C10: 82.684848 | D10: 82.651515 | E10: 82.651515 | F10: 82.735088 | G10: 82.75731 | H10: 82.41886 | I10: 82.432749 | J10: 82.145833 | K10: 74.707143 | L10: 74.368778 | M10: 73 | N10: 73.077381 | O10: 73.171569 | P10: 72.8125 | Q10: 73 | R10: 72.939338 | S10: 73.5 | T10: 73.930952 | U10: 74.424812 | V10: 74.75 | W10: 74.833333 | X10: 74.474937 | Y10: 74.568323 | Z10: 75.075 | AA10: 75.138947 | AB10: 75.162281 | AC10: 75.346667 | AD10: 75.379808 | AE10: 75.386752 | AF10: 75.416667
A11: 13.715 | B11: 85.869748 | C11: 85.904545 | D11: 86.0625 | E11: 86 | F11: 85.904545 | G11: 85.894737 | H11: 85.781746 | I11: 85.651515 | J11: 85.633971 | K11: 85.6 | L11: 85.511905 | M11: 81.177083 | N11: 80.444664 | O11: 79.085145 | P11: 78.25 | Q11: 78.212406 | R11: 77.894444 | S11: 77.333333 | T11: 78.080128 | U11: 78.236695 | V11: 78.811012 | W11: 79.51087 | X11: 79.736232 | Y11: 79.792857 | Z11: 80.153947 | AA11: 80.095556 | AB11: 80.141667 | AC11: 80.195238 | AD11: 80.3 | AE11: 80.335185 | AF11: 80.401985
A12: 14.2467 | B12: 88.404762 | C12: 88.647059 | D12: 88.933333 | E12: 89 | F12: 89.195238 | G12: 89.166667 | H12: 88.86039 | I12: 88.591667 | J12: 88.371711 | K12: 88.021739 | L12: 88.077381 | M12: 88.307692 | N12: 88.218254 | O12: 88.292857 | P12: 84.074176 | Q12: 84 | R12: 82.85641 | S12: 83.199405 | T12: 84.269697 | U12: 84.928571 | V12: 85.538462 | W12: 85.765568 | X12: 85.792857 | Y12: 85.888545 | Z12: 86.08194 | AA12: 86.218254 | AB12: 86.285714 | AC12: 86.292857 | AD12: 86.325758 | AE12: 86.458042 | AF12: 86.502564
A13: 14.7783 | B13: 89.589572 | C13: 89.583591 | D13: 89.605556 | E13: 89.881944 | F13: 90.25 | G13: 90.533937 | H13: 90.644958 | I13: 90.5 | J13: 90.126984 | K13: 89.6 | L13: 89.371711 | M13: 89.341667 | N13: 89.25 | O13: 89.403704 | P13: 89.384615 | Q13: 89.240385 | R13: 87.216374 | S13: 86.111111 | T13: 86.218254 | U13: 86.464103 | V13: 88 | W13: 88.3 | X13: 88.351648 | Y13: 88.289916 | Z13: 88.36039 | AA13: 88.577381 | AB13: 88.873016 | AC13: 88.909091 | AD13: 88.972222 | AE13: 89.026316 | AF13: 89.066964
... A32: 24.88 | B32: 93.3 | C32: 93.255435 | D32: 93.281746 | E32: 93.186343 | F32: 93.188988 | G32: 93.191392 | H32: 93.205263 | I32: 93.205263 | J32: 93.2 | K32: 93.196154 | L32: 93.142857 | M32: 93.179549 | N32: 93.125 | O32: 93.248856 | P32: 93.066667 | Q32: 92.923077 | R32: 92.932184 | S32: 93.308424 | T32: 93.201417 | U32: 93.5 | V32: 93.722222 | W32: 93.914855 | X32: 95.285714 | Y32: 95.440972 | Z32: 96.191392 | AA32: 102.22291 | AB32: 103.65686 | AC32: 104.58333 | AD32: 105.40455 | AE32: 106.94281 | AF32: 107.1

Sheet RF_R50_p90
A1: FeO \ Fe | B1: 37.3072 | C1: 37.973 | D1: 38.6387 | E1: 39.3045 | F1: 39.9702 | G1: 40.636 | H1: 41.3018 | I1: 41.9675 | J1: 42.6333 | K1: 43.299 | L1: 43.9648 | M1: 44.6306 | N1: 45.2963 | O1: 45.9621 | P1: 46.6278 | Q1: 47.2936 | R1: 47.9594 | S1: 48.6251 | T1: 49.2909 | U1: 49.9566 | V1: 50.6224 | W1: 51.2882 | X1: 51.9539 | Y1: 52.6197 | Z1: 53.2854 | AA1: 53.9512 | AB1: 54.617 | AC1: 55.2827 | AD1: 55.9485 | AE1: 56.6142 | AF1: 57.28
A2: 8.93 | B2: 75.75 | C2: 75.738158 | D2: 75.75 | E2: 75.727879 | F2: 75.696087 | G2: 75.631579 | H2: 75.414519 | I2: 75.409561 | J2: 76.173077 | K2: 76.145238 | L2: 76.145238 | M2: 76.770085 | N2: 77.004762 | O2: 77.333333 | P2: 77.352941 | Q2: 77.308173 | R2: 77.195417 | S2: 77.55625 | T2: 78.135385 | U2: 78.601111 | V2: 79.8 | W2: 80.005 | X2: 80.005 | Y2: 80.067227 | Z2: 80.158772 | AA2: 80.307037 | AB2: 80.564286 | AC2: 80.564286 | AD2: 80.69375 | AE2: 80.830556 | AF2: 81.559091
A3: 9.4617 | B3: 75.882353 | C3: 75.727879 | D3: 75.727879 | E3: 75.7 | F3: 75.625658 | G3: 75.409561 | H3: 75.183636 | I3: 75.146753 | J3: 75.804211 | K3: 76.064286 | L3: 76.303333 | M3: 76.733333 | N3: 77 | O3: 77.333333 | P3: 77.346833 | Q3: 77.307692 | R3: 77.195417 | S3: 77.55625 | T3: 78.135385 | U3: 78.601111 | V3: 79.8 | W3: 80.005 | X3: 80.005 | Y3: 80.067227 | Z3: 80.158772 | AA3: 80.307037 | AB3: 80.564286 | AC3: 80.647321 | AD3: 80.830556 | AE3: 81.559091 | AF3: 81.611818
A4: 9.9933 | B4: 76 | C4: 76.223077 | D4: 76.4625 | E4: 75.805714 | F4: 75.625658 | G4: 75.300769 | H4: 75.057143 | I4: 74.917857 | J4: 75.005556 | K4: 75.787143 | L4: 76.231222 | M4: 76.733333 | N4: 76.9 | O4: 77.304682 | P4: 77.312829 | Q4: 77.168182 | R4: 77.078322 | S4: 77.476398 | T4: 77.952632 | U4: 78.548804 | V4: 79.658571 | W4: 80.005 | X4: 80.005 | Y4: 80.144361 | Z4: 80.18 | AA4: 80.388889 | AB4: 80.647321 | AC4: 80.647321 | AD4: 80.830556 | AE4: 81.559091 | AF4: 81.611818
A5: 10.525 | B5: 75.183636 | C5: 75.631579 | D5: 75.511538 | E5: 75.835714 | F5: 76.048413 | G5: 76.125543 | H5: 74.848205 | I5: 74.555556 | J5: 74.706723 | K5: 74.752778 | L5: 75.827689 | M5: 76.504167 | N5: 76.439205 | O5: 76.836667 | P5: 76.87375 | Q5: 76.669231 | R5: 76.542045 | S5: 77.168182 | T5: 77.876389 | U5: 78.502632 | V5: 79.539161 | W5: 79.586538 | X5: 79.586538 | Y5: 80.005 | Z5: 80.067227 | AA5: 80.158772 | AB5: 80.307037 | AC5: 80.307037 | AD5: 80.647321 | AE5: 80.69375 | AF5: 80.830556
A6: 11.0567 | B6: 80.546154 | C6: 79.47 | D6: 77.8675 | E6: 74.52437 | F6: 75.041556 | G6: 75.083696 | H6: 75.071978 | I6: 75.055556 | J6: 75.291667 | K6: 74.22013 | L6: 74.375 | M6: 76.171053 | N6: 76.439205 | O6: 76.550556 | P6: 76.541667 | Q6: 77.091342 | R6: 77.095714 | S6: 77.438194 | T6: 77.917857 | U6: 78.45615 | V6: 79.539161 | W6: 79.586538 | X6: 79.586538 | Y6: 80.005 | Z6: 80.067227 | AA6: 80.158772 | AB6: 80.307037 | AC6: 80.307037 | AD6: 80.647321 | AE6: 82.833484 | AF6: 82.947436
A7: 11.5883 | B7: 93.210902 | C7: 86.07381 | D7: 85.502941 | E7: 79.533333 | F7: 79.123077 | G7: 75.755 | H7: 73.91875 | I7: 74.2 | J7: 74.669231 | K7: 75.05625 | L7: 75.6 | M7: 76.600714 | N7: 77.304682 | O7: 77.334615 | P7: 77.267273 | Q7: 77.174704 | R7: 77.1025 | S7: 77.446154 | T7: 77.929464 | U7: 78.45615 | V7: 79.549242 | W7: 79.626573 | X7: 79.626573 | Y7: 80.005 | Z7: 80.067227 | AA7: 82.647802 | AB7: 82.753571 | AC7: 83.17 | AD7: 83.902857 | AE7: 84.594976 | AF7: 84.870909
A8: 12.12 | B8: 93.113333 | C8: 93.333333 | D8: 93.734468 | E8: 92.699077 | F8: 85.900909 | G8: 81.8375 | H8: 79.728458 | I8: 79.375 | J8: 75.701429 | K8: 75.733684 | L8: 76.300435 | M8: 76.546465 | N8: 77.049107 | O8: 77.480435 | P8: 77.6 | Q8: 77.181818 | R8: 76.906593 | S8: 77.206087 | T8: 77.900476 | U8: 78.45671 | V8: 80.064052 | W8: 80.69375 | X8: 82.478571 | Y8: 82.637013 | Z8: 83.251316 | AA8: 84.351538 | AB8: 84.736471 | AC8: 85.636364 | AD8: 86.060084 | AE8: 86.298052 | AF8: 87.620513
A9: 12.6517 | B9: 93.751923 | C9: 93.690179 | D9: 93.94 | E9: 93.91619 | F9: 93.734468 | G9: 93.602791 | H9: 87.563393 | I9: 86 | J9: 81.737879 | K9: 80.56 | L9: 80.244571 | M9: 77.004348 | N9: 76.869474 | O9: 77.091342 | P9: 77.446154 | Q9: 77.095714 | R9: 77.16875 | S9: 77.75 | T9: 79.362605 | U9: 80.47094 | V9: 83.902857 | W9: 84.334615 | X9: 84.641754 | Y9: 85.079576 | Z9: 86.228571 | AA9: 86.504545 | AB9: 87.909848 | AC9: 88.398841 | AD9: 90.355 | AE9: 90.355 | AF9: 90.75625
A10: 13.1833 | B10: 94.8755 | C10: 94.625 | D10: 94.8755 | E10: 94.880889 | F10: 94.502174 | G10: 94.091818 | H10: 94.006667 | I10: 93.861429 | J10: 93.66875 | K10: 87.574286 | L10: 87.182386 | M10: 82.22013 | N10: 81.616667 | O10: 81.003846 | P10: 78.715584 | Q10: 79.357143 | R10: 79.335714 | S10: 79.744615 | T10: 81.727273 | U10: 83.935714 | V10: 86.293506 | W10: 87.561538 | X10: 87.669231 | Y10: 88.729545 | Z10: 90.355 | AA10: 91.384167 | AB10: 91.94375 | AC10: 92.695077 | AD10: 92.835714 | AE10: 92.858095 | AF10: 93.115909
A11: 13.715 | B11: 94.666667 | C11: 94.740936 | D11: 95.334615 | E11: 95.308173 | F11: 95.086111 | G11: 94.8755 | H11: 94.527018 | I11: 93.94 | J11: 93.861429 | K11: 93.620513 | L11: 93.268571 | M11: 89.740217 | N11: 89.129167 | O11: 87.454545 | P11: 86.048739 | Q11: 85.913636 | R11: 85.617004 | S11: 85.196154 | T11: 87.182386 | U11: 88.336364 | V11: 90.469231 | W11: 91.645238 | X11: 92 | Y11: 92.062917 | Z11: 92.874118 | AA11: 93.288874 | AB11: 93.3775 | AC11: 93.548052 | AD11: 93.72619 | AE11: 93.846154 | AF11: 93.847253
A12: 14.2467 | B12: 94.8525 | C12: 95.153846 | D12: 95.833721 | E12: 95.929048 | F12: 96.071978 | G12: 96.158462 | H12: 95.668182 | I12: 95.277508 | J12: 95 | K12: 94.430714 | L12: 93.762637 | M12: 94.006667 | N12: 94 | O12: 94.880889 | P12: 91 | Q12: 90.836957 | R12: 90.215079 | S12: 89.883007 | T12: 90.091342 | U12: 91.753571 | V12: 93.5 | W12: 94.317544 | X12: 94.818182 | Y12: 94.770085 | Z12: 94.945 | AA12: 95.5 | AB12: 95.503846 | AC12: 95.45 | AD12: 95.557143 | AE12: 95.708021 | AF12: 95.834615
A13: 14.7783 | B13: 96.127885 | C13: 96.079231 | D13: 95.909612 | E13: 96.193394 | F13: 96.578947 | G13: 96.945238 | H13: 97.137013 | I13: 97.045909 | J13: 96.272727 | K13: 95.753571 | L13: 95.526123 | M13: 95.5 | N13: 94.923626 | O13: 96.144361 | P13: 97.095455 | Q13: 97.609205 | R13: 94.759524 | S13: 93.657288 | T13: 92.571429 | U13: 92.421805 | V13: 95.050882 | W13: 95.37004 | X13: 95.866746 | Y13: 95.8 | Z13: 95.966667 | AA13: 96.546203 | AB13: 96.712217 | AC13: 96.712217 | AD13: 96.774126 | AE13: 96.823864 | AF13: 96.823864
... A32: 24.88 | B32: 99.610417 | C32: 99.5 | D32: 99.431868 | E32: 99.411765 | F32: 99.411765 | G32: 99.411765 | H32: 99.356536 | I32: 99.345639 | J32: 99.345639 | K32: 99.401176 | L32: 99.401176 | M32: 99.298039 | N32: 99.183836 | O32: 99.412255 | P32: 99.5 | Q32: 99.358824 | R32: 99.591667 | S32: 101.83333 | T32: 101.90286 | U32: 103.45909 | V32: 104.09748 | W32: 104.80182 | X32: 106.34564 | Y32: 106.38615 | Z32: 106.68157 | AA32: 107.90909 | AB32: 107.92857 | AC32: 108.23676 | AD32: 108.3 | AE32: 108.56339 | AF32: 108.69308

Sheet RF_R90_p10
A1: FeO \ Fe | B1: 37.3072 | C1: 37.973 | D1: 38.6387 | E1: 39.3045 | F1: 39.9702 | G1: 40.636 | H1: 41.3018 | I1: 41.9675 | J1: 42.6333 | K1: 43.299 | L1: 43.9648 | M1: 44.6306 | N1: 45.2963 | O1: 45.9621 | P1: 46.6278 | Q1: 47.2936 | R1: 47.9594 | S1: 48.6251 | T1: 49.2909 | U1: 49.9566 | V1: 50.6224 | W1: 51.2882 | X1: 51.9539 | Y1: 52.6197 | Z1: 53.2854 | AA1: 53.9512 | AB1: 54.617 | AC1: 55.2827 | AD1: 55.9485 | AE1: 56.6142 | AF1: 57.28
A2: 8.93 | B2: 67.213547 | C2: 67.213547 | D2: 67.214286 | E2: 67.249138 | F2: 67.25 | G2: 67.298571 | H2: 67.398889 | I2: 67.453091 | J2: 67.472982 | K2: 67.466154 | L2: 67.541346 | M2: 67.687171 | N2: 67.785714 | O2: 67.833333 | P2: 67.878957 | Q2: 67.878957 | R2: 67.882353 | S2: 67.916667 | T2: 67.962857 | U2: 68 | V2: 68 | W2: 68 | X2: 68 | Y2: 68 | Z2: 68 | AA2: 68 | AB2: 68 | AC2: 68 | AD2: 67.962857 | AE2: 67.962857 | AF2: 67.962857
A3: 9.4617 | B3: 67.1875 | C3: 67.206207 | D3: 67.213547 | E3: 67.23867 | F3: 67.23867 | G3: 67.249138 | H3: 67.285714 | I3: 67.427381 | J3: 67.466154 | K3: 67.454545 | L3: 67.538462 | M3: 67.666667 | N3: 67.748913 | O3: 67.817614 | P3: 67.833333 | Q3: 67.833333 | R3: 67.868323 | S3: 67.908658 | T3: 67.935417 | U3: 67.94375 | V3: 67.949444 | W3: 67.962857 | X3: 67.962857 | Y3: 67.94375 | Z3: 67.94375 | AA3: 67.94375 | AB3: 68 | AC3: 68.5 | AD3: 68.578195 | AE3: 68.587745 | AF3: 68.587745
A4: 9.9933 | B4: 67.1875 | C4: 67.1875 | D4: 67.1875 | E4: 67.19875 | F4: 67.206207 | G4: 67.206207 | H4: 67.276667 | I4: 67.298571 | J4: 67.398889 | K4: 67.438857 | L4: 67.5 | M4: 67.666667 | N4: 67.705294 | O4: 67.782143 | P4: 67.8 | Q4: 67.785714 | R4: 67.8 | S4: 67.878957 | T4: 67.895785 | U4: 67.903941 | V4: 67.909091 | W4: 67.912648 | X4: 68.071429 | Y4: 68.416667 | Z4: 68.554545 | AA4: 68.554545 | AB4: 68.554545 | AC4: 68.554545 | AD4: 68.554545 | AE4: 68.554545 | AF4: 68.554545
A5: 10.525 | B5: 67 | C5: 67.06625 | D5: 67.076923 | E5: 67.1875 | F5: 67.1875 | G5: 67.1875 | H5: 67.1875 | I5: 67.25 | J5: 67.307692 | K5: 67.370833 | L5: 67.5 | M5: 67.6 | N5: 67.666667 | O5: 67.68 | P5: 67.705294 | Q5: 67.699565 | R5: 67.722222 | S5: 67.798571 | T5: 67.935417 | U5: 68.331818 | V5: 68.459829 | W5: 68.496154 | X5: 68.496154 | Y5: 68.496154 | Z5: 68.496154 | AA5: 68.496154 | AB5: 68.496154 | AC5: 68.496154 | AD5: 68.496154 | AE5: 68.496154 | AF5: 68.496154
A6: 11.0567 | B6: 67.307692 | C6: 67.25 | D6: 67.214286 | E6: 67.0625 | F6: 67.082692 | G6: 67.186397 | H6: 67.1875 | I6: 67.214286 | J6: 67.276667 | K6: 67.302484 | L6: 67.453091 | M6: 67.623611 | N6: 67.666667 | O6: 67.722222 | P6: 67.748684 | Q6: 68.27177 | R6: 68.416667 | S6: 68.5 | T6: 68.526471 | U6: 68.537557 | V6: 68.544755 | W6: 68.554545 | X6: 68.554545 | Y6: 68.554545 | Z6: 68.554545 | AA6: 68.554545 | AB6: 68.554545 | AC6: 68.554545 | AD6: 68.554545 | AE6: 68.725134 | AF6: 68.8125
A7: 11.5883 | B7: 68.2 | C7: 67.68675 | D7: 67.6 | E7: 67.307692 | F7: 67.307692 | G7: 67.25 | H7: 67.083333 | I7: 67.166667 | J7: 67.25 | K7: 67.307692 | L7: 67.5 | M7: 67.68 | N7: 68.277273 | O7: 68.416667 | P7: 68.5 | Q7: 68.5 | R7: 68.5 | S7: 68.587745 | T7: 68.614957 | U7: 68.641729 | V7: 68.664286 | W7: 68.666667 | X7: 68.666667 | Y7: 68.666667 | Z7: 68.666667 | AA7: 68.915909 | AB7: 68.928022 | AC7: 68.928571 | AD7: 68.94375 | AE7: 69.064762 | AF7: 69.082692
A8: 12.12 | B8: 68.367579 | C8: 68.367579 | D8: 68.386842 | E8: 68.248529 | F8: 67.875 | G8: 67.561806 | H8: 67.453091 | I8: 67.5 | J8: 67.3875 | K8: 67.545455 | L8: 67.875 | M8: 68.460839 | N8: 68.666667 | O8: 68.873214 | P8: 68.936607 | Q8: 68.817614 | R8: 68.720588 | S8: 68.833333 | T8: 68.857143 | U8: 68.8875 | V8: 68.913889 | W8: 69 | X8: 69.185417 | Y8: 69.24881 | Z8: 69.290278 | AA8: 69.472982 | AB8: 69.498 | AC8: 69.5 | AD8: 69.5 | AE8: 69.521429 | AF8: 69.621591
A9: 12.6517 | B9: 68.472982 | C9: 68.466154 | D9: 68.472982 | E9: 68.472982 | F9: 68.466154 | G9: 68.497368 | H9: 68.357143 | I9: 68.346377 | J9: 68 | K9: 67.8875 | L9: 68.111111 | M9: 68.153462 | N9: 68.398889 | O9: 68.6875 | P9: 69 | Q9: 69.065882 | R9: 69.090909 | S9: 69.330769 | T9: 69.666667 | U9: 69.443478 | V9: 69.5 | W9: 69.521429 | X9: 69.666667 | Y9: 69.678667 | Z9: 69.691827 | AA9: 69.691827 | AB9: 69.764426 | AC9: 69.785404 | AD9: 69.888 | AE9: 69.888 | AF9: 69.888
A10: 13.1833 | B10: 68.5 | C10: 68.472982 | D10: 68.497368 | E10: 68.619048 | F10: 68.772727 | G10: 68.833333 | H10: 68.833333 | I10: 68.841228 | J10: 68.833333 | K10: 68.466154 | L10: 68.526471 | M10: 68.496154 | N10: 68.642857 | O10: 68.923077 | P10: 68.6875 | Q10: 69 | R10: 69.153846 | S10: 69.926623 | T10: 70 | U10: 70.198182 | V10: 70.271542 | W10: 70.248529 | X10: 70 | Y10: 69.888 | Z10: 70 | AA10: 70 | AB10: 70 | AC10: 70.070168 | AD10: 70.070168 | AE10: 70.070168 | AF10: 70.071429
A11: 13.715 | B11: 69.46375 | C11: 70.701961 | D11: 70.843357 | E11: 70.903896 | F11: 70.903896 | G11: 70.856044 | H11: 70.903896 | I11: 70.856044 | J11: 70.856044 | K11: 70.996296 | L11: 71.333333 | M11: 71.1225 | N11: 71.285714 | O11: 71.466667 | P11: 71.5 | Q11: 71.93375 | R11: 71.64011 | S11: 71.5 | T11: 71.961037 | U11: 71.961037 | V11: 72.165789 | W11: 72.344872 | X11: 72.333333 | Y11: 72.282143 | Z11: 72.282143 | AA11: 71.8975 | AB11: 71.576608 | AC11: 71.61 | AD11: 71.61 | AE11: 71.61 | AF11: 71.61
A12: 14.2467 | B12: 78.496667 | C12: 78.464444 | D12: 78.496667 | E12: 78.464444 | F12: 78.442105 | G12: 78.496667 | H12: 78.496667 | I12: 78.442105 | J12: 78.412281 | K12: 78.442105 | L12: 80.746429 | M12: 80.894615 | N12: 81.053846 | O12: 80.923077 | P12: 78.126482 | Q12: 78.218182 | R12: 76.141071 | S12: 76.747727 | T12: 78 | U12: 77.108333 | V12: 75.154105 | W12: 75.554545 | X12: 75.52409 | Y12: 75.54385 | Z12: 75.763235 | AA12: 75.763235 | AB12: 75.828571 | AC12: 75.763235 | AD12: 75.316571 | AE12: 75.152105 | AF12: 75.152105
A13: 14.7783 | B13: 82.569286 | C13: 82.569286 | D13: 82.540909 | E13: 82.569286 | F13: 82.571429 | G13: 82.568831 | H13: 82.568831 | I13: 82.612179 | J13: 83.5 | K13: 83.461538 | L13: 83.460839 | M13: 83.589583 | N13: 83.58125 | O13: 83.817614 | P13: 83.461538 | Q13: 83.333333 | R13: 82.099091 | S13: 81.73538 | T13: 82.141905 | U13: 82 | V13: 82.613846 | W13: 82.795 | X13: 81.866667 | Y13: 80.492857 | Z13: 80.492857 | AA13: 80.405 | AB13: 80.405 | AC13: 80.405 | AD13: 80.405 | AE13: 80.405 | AF13: 80.405
... A32: 24.88 | B32: 88.55 | C32: 88.636364 | D32: 88.642208 | E32: 88.721429 | F32: 88.726768 | G32: 88.721429 | H32: 88.726768 | I32: 88.714286 | J32: 88.776923 | K32: 88.769231 | L32: 88.898 | M32: 88.995 | N32: 89.181818 | O32: 89.3875 | P32: 89.415909 | Q32: 89.373864 | R32: 89.632727 | S32: 90.291979 | T32: 90.277273 | U32: 90.642857 | V32: 90.777778 | W32: 90.789474 | X32: 90.846154 | Y32: 90.841228 | Z32: 90.875 | AA32: 93.470196 | AB32: 94.264 | AC32: 94.445 | AD32: 94.52381 | AE32: 101.31202 | AF32: 101.62039

Sheet RF_R90_mean
A1: FeO \ Fe | B1: 37.3072 | C1: 37.973 | D1: 38.6387 | E1: 39.3045 | F1: 39.9702 | G1: 40.636 | H1: 41.3018 | I1: 41.9675 | J1: 42.6333 | K1: 43.299 | L1: 43.9648 | M1: 44.6306 | N1: 45.2963 | O1: 45.9621 | P1: 46.6278 | Q1: 47.2936 | R1: 47.9594 | S1: 48.6251 | T1: 49.2909 | U1: 49.9566 | V1: 50.6224 | W1: 51.2882 | X1: 51.9539 | Y1: 52.6197 | Z1: 53.2854 | AA1: 53.9512 | AB1: 54.617 | AC1: 55.2827 | AD1: 55.9485 | AE1: 56.6142 | AF1: 57.28
A2: 8.93 | B2: 69.792857 | C2: 69.792857 | D2: 69.804762 | E2: 69.833333 | F2: 69.84413 | G2: 69.932184 | H2: 70.045549 | I2: 70.181818 | J2: 70.296703 | K2: 70.333333 | L2: 70.452273 | M2: 70.875 | N2: 71.125 | O2: 71.352941 | P2: 71.395652 | Q2: 71.388889 | R2: 71.303846 | S2: 71.5 | T2: 71.570724 | U2: 71.644958 | V2: 71.763889 | W2: 71.781746 | X2: 71.781746 | Y2: 71.781746 | Z2: 71.734604 | AA2: 71.734604 | AB2: 71.734604 | AC2: 71.75 | AD2: 71.734604 | AE2: 71.734604 | AF2: 71.734604
A3: 9.4617 | B3: 69.768717 | C3: 69.736842 | D3: 69.75 | E3: 69.777668 | F3: 69.773657 | G3: 69.828431 | H3: 69.896825 | I3: 70.090909 | J3: 70.231283 | K3: 70.264912 | L3: 70.4 | M3: 70.75 | N3: 71 | O3: 71.228758 | P3: 71.281746 | Q3: 71.275253 | R3: 71.226496 | S3: 71.395652 | T3: 71.5 | U3: 71.538462 | V3: 71.604348 | W3: 71.609903 | X3: 71.615385 | Y3: 71.609903 | Z3: 71.609903 | AA3: 71.609903 | AB3: 71.702941 | AC3: 72.633971 | AD3: 72.75 | AE3: 72.75 | AF3: 72.757353
A4: 9.9933 | B4: 69.875 | C4: 69.866071 | D4: 69.857143 | E4: 69.763305 | F4: 69.716578 | G4: 69.730303 | H4: 69.837719 | I4: 69.933333 | J4: 70.047619 | K4: 70.212406 | L4: 70.333333 | M4: 70.705882 | N4: 70.866667 | O4: 71.129167 | P4: 71.196154 | Q4: 71.160256 | R4: 71.133333 | S4: 71.303846 | T4: 71.4 | U4: 71.458042 | V4: 71.538462 | W4: 71.538462 | X4: 71.857143 | Y4: 72.455769 | Z4: 72.617216 | AA4: 72.633971 | AB4: 72.633971 | AC4: 72.633971 | AD4: 72.63961 | AE4: 72.644958 | AF4: 72.617216
A5: 10.525 | B5: 69.472136 | C5: 69.538462 | D5: 69.545455 | E5: 69.820856 | F5: 69.823529 | G5: 69.811012 | H5: 69.692308 | I5: 69.811012 | J5: 69.888889 | K5: 70 | L5: 70.25 | M5: 70.605556 | N5: 70.692308 | O5: 70.870833 | P5: 71 | Q5: 70.981481 | R5: 70.950957 | S5: 71.172619 | T5: 71.466667 | U5: 72.184659 | V5: 72.333333 | W5: 72.348077 | X5: 72.348077 | Y5: 72.348077 | Z5: 72.379863 | AA5: 72.379863 | AB5: 72.379863 | AC5: 72.391304 | AD5: 72.391304 | AE5: 72.379863 | AF5: 72.333333
A6: 11.0567 | B6: 70.311741 | C6: 70.13961 | D6: 70 | E6: 69.571429 | F6: 69.660256 | G6: 69.828431 | H6: 69.896825 | I6: 70 | J6: 70.087121 | K6: 70 | L6: 70.153846 | M6: 70.696154 | N6: 70.816527 | O6: 71.115132 | P6: 71.204167 | Q6: 72.025 | R6: 72.052778 | S6: 72.281746 | T6: 72.4 | U6: 72.491379 | V6: 72.644958 | W6: 72.648529 | X6: 72.644958 | Y6: 72.648529 | Z6: 72.644958 | AA6: 72.644958 | AB6: 72.61204 | AC6: 72.575188 | AD6: 72.568323 | AE6: 73.042572 | AF6: 73.074176
A7: 11.5883 | B7: 81.933333 | C7: 72.899749 | D7: 72.320513 | E7: 70.545455 | F7: 70.428571 | G7: 70 | H7: 69.75 | I7: 69.9375 | J7: 70.142857 | K7: 70.390476 | L7: 70.705882 | M7: 71.322917 | N7: 72.333333 | O7: 72.514706 | P7: 72.5 | Q7: 72.5 | R7: 72.357143 | S7: 72.733333 | T7: 72.8625 | U7: 73 | V7: 73.148352 | W7: 73.142857 | X7: 73.058824 | Y7: 73.044466 | Z7: 73.044466 | AA7: 73.5 | AB7: 73.567251 | AC7: 73.666667 | AD7: 73.735088 | AE7: 74 | AF7: 74.054094
A8: 12.12 | B8: 82.753036 | C8: 82.753036 | D8: 82.654762 | E8: 80.088942 | F8: 73.936594 | G8: 71.707386 | H8: 71.240385 | I8: 71.285714 | J8: 70.689904 | K8: 71.352941 | L8: 72.064583 | M8: 72.930952 | N8: 73.470175 | O8: 73.925824 | P8: 73.885621 | Q8: 73.222222 | R8: 72.93797 | S8: 73.218254 | T8: 73.452083 | U8: 73.47619 | V8: 73.615385 | W8: 73.688259 | X8: 74.091667 | Y8: 74.233032 | Z8: 74.4375 | AA8: 74.75 | AB8: 74.795833 | AC8: 74.927083 | AD8: 75.085145 | AE8: 75.102632 | AF8: 75.375
A9: 12.6517 | B9: 82.777778 | C9: 82.777778 | D9: 82.63961 | E9: 82.41886 | F9: 82.408333 | G9: 82.279221 | H9: 76.262443 | I9: 75.281746 | J9: 73.166667 | K9: 72.902381 | L9: 73.138095 | M9: 72.6 | N9: 72.856818 | O9: 73.405882 | P9: 73.578947 | Q9: 73.5 | R9: 73.400327 | S9: 73.673333 | T9: 74.25 | U9: 74 | V9: 74.363971 | W9: 74.474937 | X9: 74.78869 | Y9: 74.85 | Z9: 75.102632 | AA9: 75.111111 | AB9: 75.345238 | AC9: 75.41886 | AD9: 76.215385 | AE9: 76.258242 | AF9: 76.258242
A10: 13.1833 | B10: 83.091912 | C10: 83.091912 | D10: 82.88986 | E10: 82.773504 | F10: 82.788889 | G10: 82.753036 | H10: 82.585227 | I10: 82.494949 | J10: 82.059649 | K10: 76.4699 | L10: 76.219551 | M10: 73.780193 | N10: 73.8125 | O10: 73.928571 | P10: 73.343137 | Q10: 73.615385 | R10: 73.47619 | S10: 74.205263 | T10: 74.848077 | U10: 75.310096 | V10: 75.656863 | W10: 75.79057 | X10: 75.559028 | Y10: 75.773504 | Z10: 76.433036 | AA10: 76.577381 | AB10: 76.577381 | AC10: 76.846053 | AD10: 76.897368 | AE10: 76.9 | AF10: 76.96875
A11: 13.715 | B11: 85.275253 | C11: 85.333333 | D11: 85.333333 | E11: 85.285948 | F11: 85.179144 | G11: 85.179144 | H11: 85 | I11: 84.940972 | J11: 84.897368 | K11: 84.888545 | L11: 84.795833 | M11: 81.256579 | N11: 80.666667 | O11: 79.5 | P11: 78.755952 | Q11: 78.720779 | R11: 78.275253 | S11: 77.935417 | T11: 78.535897 | U11: 78.766968 | V11: 79.5 | W11: 80.454545 | X11: 80.666667 | Y11: 80.677083 | Z11: 80.930288 | AA11: 80.904545 | AB11: 80.909091 | AC11: 81 | AD11: 81.149306 | AE11: 81.149306 | AF11: 81.200893
A12: 14.2467 | B12: 87.87451 | C12: 88.078704 | D12: 88.072751 | E12: 88.105556 | F12: 88.247475 | G12: 88.307692 | H12: 88.188988 | I12: 88.071429 | J12: 88.021739 | K12: 87.785714 | L12: 87.891813 | M12: 88.078704 | N12: 88 | O12: 88 | P12: 84.285714 | Q12: 84.339744 | R12: 83.538462 | S12: 83.723636 | T12: 84.820856 | U12: 85.568323 | V12: 86.083916 | W12: 86.550505 | X12: 86.630682 | Y12: 86.674242 | Z12: 86.870833 | AA12: 87.020833 | AB12: 87.057566 | AC12: 87.071429 | AD12: 87.080128 | AE12: 87.142857 | AF12: 87.167832
A13: 14.7783 | B13: 89.576974 | C13: 89.461538 | D13: 89.158333 | E13: 89.301994 | F13: 89.416409 | G13: 89.647727 | H13: 89.900966 | I13: 89.952273 | J13: 90 | K13: 89.636364 | L13: 89.537433 | M13: 89.545455 | N13: 89.267943 | O13: 89.537433 | P13: 89.442222 | Q13: 89.2 | R13: 87.643529 | S13: 86.636364 | T13: 86.666667 | U13: 87.020833 | V13: 88.689904 | W13: 89.333333 | X13: 89.656863 | Y13: 89.333333 | Z13: 89.428571 | AA13: 89.718421 | AB13: 89.891813 | AC13: 89.9375 | AD13: 89.9375 | AE13: 89.939338 | AF13: 89.94281
... A32: 24.88 | B32: 93.729532 | C32: 93.666667 | D32: 93.559028 | E32: 93.511905 | F32: 93.52381 | G32: 93.486842 | H32: 93.5 | I32: 93.486842 | J32: 93.630682 | K32: 93.544231 | L32: 93.615385 | M32: 93.620192 | N32: 94.272727 | O32: 94.468627 | P32: 94.834842 | Q32: 94.919872 | R32: 95.179144 | S32: 96.256579 | T32: 96.264912 | U32: 96.869318 | V32: 96.906926 | W32: 96.902381 | X32: 97.080128 | Y32: 97.080128 | Z32: 97.39819 | AA32: 103 | AB32: 103.73901 | AC32: 104.38462 | AD32: 104.77951 | AE32: 106.6 | AF32: 106.77778

Sheet RF_R90_p90
A1: FeO \ Fe | B1: 37.3072 | C1: 37.973 | D1: 38.6387 | E1: 39.3045 | F1: 39.9702 | G1: 40.636 | H1: 41.3018 | I1: 41.9675 | J1: 42.6333 | K1: 43.299 | L1: 43.9648 | M1: 44.6306 | N1: 45.2963 | O1: 45.9621 | P1: 46.6278 | Q1: 47.2936 | R1: 47.9594 | S1: 48.6251 | T1: 49.2909 | U1: 49.9566 | V1: 50.6224 | W1: 51.2882 | X1: 51.9539 | Y1: 52.6197 | Z1: 53.2854 | AA1: 53.9512 | AB1: 54.617 | AC1: 55.2827 | AD1: 55.9485 | AE1: 56.6142 | AF1: 57.28
A2: 8.93 | B2: 74.529804 | C2: 74.502941 | D2: 74.502941 | E2: 74.535556 | F2: 74.529804 | G2: 74.651667 | H2: 74.870476 | I2: 75.414519 | J2: 76.4 | K2: 76.358929 | L2: 76.417105 | M2: 77 | N2: 77.182386 | O2: 77.522899 | P2: 77.56625 | Q2: 77.535556 | R2: 77.308173 | S2: 77.555556 | T2: 78.153846 | U2: 78.601111 | V2: 80.647321 | W2: 81.055556 | X2: 81.055556 | Y2: 81.055556 | Z2: 81.559091 | AA2: 81.611818 | AB2: 81.611818 | AC2: 81.611818 | AD2: 81.611818 | AE2: 81.611818 | AF2: 81.611818
A3: 9.4617 | B3: 74.502941 | C3: 74.317544 | D3: 74.277033 | E3: 74.3375 | F3: 74.317544 | G3: 74.387821 | H3: 74.529804 | I3: 75.101111 | J3: 76 | K3: 76.231222 | L3: 76.417105 | M3: 76.643277 | N3: 76.947059 | O3: 77.28 | P3: 77.307692 | Q3: 77.28 | R3: 77 | S3: 77.300769 | T3: 77.900476 | U3: 78.455245 | V3: 80.540756 | W3: 80.775 | X3: 80.775 | Y3: 80.775 | Z3: 81.055556 | AA3: 81.559091 | AB3: 81.559091 | AC3: 81.631818 | AD3: 81.631818 | AE3: 81.631818 | AF3: 81.631818
A4: 9.9933 | B4: 75.201429 | C4: 75.201429 | D4: 75.358271 | E4: 74.387821 | F4: 74.16875 | G4: 74.187798 | H4: 74.3375 | I4: 74.78 | J4: 75.134286 | K4: 75.847368 | L4: 76.303333 | M4: 76.504167 | N4: 76.733333 | O4: 77.166667 | P4: 77.182386 | Q4: 77.047619 | R4: 76.71619 | S4: 77.1125 | T4: 77.875 | U4: 78.431169 | V4: 80.540756 | W4: 80.775 | X4: 80.775 | Y4: 81.248413 | Z4: 81.559091 | AA4: 81.631818 | AB4: 81.631818 | AC4: 81.631818 | AD4: 81.631818 | AE4: 81.631818 | AF4: 81.631818
A5: 10.525 | B5: 74.134058 | C5: 74.585 | D5: 74.5 | E5: 74.95 | F5: 75.071978 | G5: 75.217857 | H5: 74.210902 | I5: 74.529804 | J5: 74.905952 | K5: 74.930159 | L5: 76.052857 | M5: 76.401667 | N5: 76.375962 | O5: 76.775641 | P5: 76.87375 | Q5: 76.714286 | R5: 76.2925 | S5: 76.833333 | T5: 77.847253 | U5: 78.581053 | V5: 80.69375 | W5: 81.248413 | X5: 81.248413 | Y5: 81.248413 | Z5: 81.559091 | AA5: 81.631818 | AB5: 81.631818 | AC5: 81.631818 | AD5: 81.631818 | AE5: 81.631818 | AF5: 81.631818
A6: 11.0567 | B6: 81.39 | C6: 80.429193 | D6: 78.818182 | E6: 75.063942 | F6: 75.385284 | G6: 75.550909 | H6: 75.75 | I6: 76.450833 | J6: 76.75625 | K6: 76.074286 | L6: 76.1025 | M6: 77.004348 | N6: 77.190303 | O6: 77.304682 | P6: 77.364773 | Q6: 77.68447 | R6: 77.6 | S6: 77.756818 | T6: 78.581053 | U6: 79.861538 | V6: 83.26866 | W6: 84.021429 | X6: 84.216387 | Y6: 84.216387 | Z6: 84.245098 | AA6: 84.402857 | AB6: 84.402857 | AC6: 84.402857 | AD6: 84.402857 | AE6: 84.852448 | AF6: 84.852448
A7: 11.5883 | B7: 94 | C7: 87.8675 | D7: 86.952059 | E7: 81.66875 | F7: 81.313765 | G7: 78.715584 | H7: 77.539161 | I7: 78.157895 | J7: 78.189803 | K7: 78.201053 | L7: 78.230769 | M7: 78.312829 | N7: 78.52437 | O7: 78.540171 | P7: 78.478571 | Q7: 78.620513 | R7: 78.548804 | S7: 78.75 | T7: 80.174 | U7: 82.305294 | V7: 85.57218 | W7: 85.931169 | X7: 85.959091 | Y7: 85.959091 | Z7: 86.004 | AA7: 86.589412 | AB7: 86.589412 | AC7: 86.6025 | AD7: 86.633929 | AE7: 87.183636 | AF7: 87.44375
A8: 12.12 | B8: 93.762637 | C8: 93.90961 | D8: 93.774126 | E8: 92.924103 | F8: 87.574286 | G8: 84.18875 | H8: 82.310256 | I8: 82.333333 | J8: 80.529412 | K8: 79.73913 | L8: 79.740217 | M8: 79.633127 | N8: 79.653623 | O8: 79.64757 | P8: 79.643277 | Q8: 79.572619 | R8: 79.827273 | S8: 80.047857 | T8: 81.672727 | U8: 83.364706 | V8: 86.432381 | W8: 87.183636 | X8: 87.44375 | Y8: 87.44375 | Z8: 87.561538 | AA8: 87.909486 | AB8: 88.013333 | AC8: 88.598162 | AD8: 89.005263 | AE8: 89.205 | AF8: 90.006667
A9: 12.6517 | B9: 93.952632 | C9: 93.822078 | D9: 93.589412 | E9: 93.573109 | F9: 93.481316 | G9: 93.375 | H9: 88.071429 | I9: 86.699123 | J9: 83.288961 | K9: 82.552448 | L9: 82.407368 | M9: 80.471355 | N9: 80.047857 | O9: 80.047857 | P9: 79.947632 | Q9: 79.912919 | R9: 80 | S9: 80.473529 | T9: 82.695804 | U9: 84.366857 | V9: 86.633929 | W9: 87.505 | X9: 87.885027 | Y9: 87.913406 | Z9: 88.924103 | AA9: 89.005263 | AB9: 89.900909 | AC9: 90 | AD9: 92.287912 | AE9: 92.308173 | AF9: 92.592929
